<?xml version="1.0"?>
<sdf version="1.6">
	<model name="delta_robot">

		<link name="world_link" />
		<link name="base">
			<self_collide>false</self_collide>
			<pose>0 0 0 0.0 -0.0 0.0</pose>
			<inertial>
				<pose>0.0 0.0 0.0 0 0 0</pose>
				<mass>3.6638315170997653</mass>
				<inertia>
					<ixx>0.008042058035953708</ixx>
					<ixy>5.516085366252809e-18</ixy>
					<ixz>-2.377869012804012e-18</ixz>
					<iyy>0.008042058035953708</iyy>
					<iyz>-3.869571330028513e-19</iyz>
					<izz>0.015838555549907964</izz>
				</inertia>
			</inertial>
			<collision name="base_collision">
				<geometry>
					<mesh>
						<uri>package://delta_robot_description/meshes/base.stl</uri>
						<scale>0.001 0.001 0.001</scale>
					</mesh>
				</geometry>
			</collision>
			<visual name="base_visual">
				<geometry>
					<mesh>
						<uri>package://delta_robot_description/meshes/base.stl</uri>
						<scale>0.001 0.001 0.001</scale>
					</mesh>
				</geometry>
				<material>
					<ambient>0.2 0.2 0.2 1</ambient>
					<diffuse>0.2 0.2 0.2 1</diffuse>
					<specular>0.5 0.5 0.5 1</specular>
				</material>
			</visual>
		</link>
		<link name="Frame">
			<self_collide>false</self_collide>
			<pose>0.0 0.0 -0.059453642384105956 0.0 -0.0 0.0</pose>
			<inertial>
				<pose>0.0 0.0 0.0 0 0 0</pose>
				<mass>74.08437500000011</mass>
				<inertia>
					<ixx>4.027796531155124</ixx>
					<ixy>8.773058652877807e-15</ixy>
					<ixz>-2.620005154345948e-15</ixz>
					<iyy>4.096484031155128</iyy>
					<iyz>2.1416006383437197e-15</iyz>
					<izz>4.613305989583342</izz>
				</inertia>
			</inertial>
			<collision name="Frame_collision">
				<geometry>
					<mesh>
						<uri>package://delta_robot_description/meshes/Frame.stl</uri>
						<scale>0.001 0.001 0.001</scale>
					</mesh>
				</geometry>
			</collision>
			<visual name="Frame_visual">
				<geometry>
					<mesh>
						<uri>package://delta_robot_description/meshes/Frame.stl</uri>
						<scale>0.001 0.001 0.001</scale>
					</mesh>
				</geometry>
				<material>
					<ambient>0.2 0.2 0.2 1</ambient>
					<diffuse>0.2 0.2 0.2 1</diffuse>
					<specular>0.5 0.5 0.5 1</specular>
				</material>
			</visual>
		</link>
		<link name="eye_to_hand_cam">
			<pose relative_to="base">0.2 0 0.035 0 1.5708 0</pose>
			<inertial>
				<mass>0.0001</mass>
				<inertia>
					<ixx>1e-9</ixx>
					<ixy>0</ixy>
					<ixz>0</ixz>
					<iyy>1e-9</iyy>
					<iyz>0</iyz>
					<izz>1e-9</izz>
				</inertia>
			</inertial>
			<collision name="camera_collision">
				<geometry>
					<box>
						<size>0.01 0.01 0.01</size>
					</box>
				</geometry>
			</collision>
			<visual name="camera_visual">
				<geometry>
					<box>
						<size>0.01 0.01 0.01</size>
					</box>
				</geometry>
			</visual>
			<sensor name="camera1" type="camera">
				<pose>0 0 0 0 0 0</pose>
				<topic>camera1/image_raw</topic>
				<update_rate>60.0</update_rate>
				<camera name="head1">
					<horizontal_fov>1.3962634</horizontal_fov>
					<image>
						<width>800</width>
						<height>800</height>
						<format>R8G8B8</format>
					</image>
					<clip>
						<near>0.02</near>
						<far>300</far>
					</clip>
					<noise>
						<type>gaussian</type>
						<mean>0.0</mean>
						<stddev>0.007</stddev>
					</noise>
				</camera>
			</sensor>
		</link>
		<link name="forearm1">
			<self_collide>false</self_collide>

			<pose>0.1039999976157913453 0.0265000002980230916 0 0 0 0</pose>
			<inertial>
				<pose>0.0525 0.0 0.0 0 0 0</pose>
				<mass>0.15</mass>
				<inertia>
					<ixx>0.000073</ixx>
					<ixy>0</ixy>
					<ixz>0</ixz>
					<iyy>0.000158</iyy>
					<iyz>0</iyz>
					<izz>0.000191</izz>
				</inertia>
			</inertial>
			<collision name="forearm1_collision">
				<pose>0.0561433036849963152 -0.0257850099915614278 -0 -0 -0 -0</pose>
				<geometry>
					<mesh>
						<uri>package://delta_robot_description/meshes/forearm1.stl</uri>
						<scale>0.001 0.001 0.001</scale>
					</mesh>
				</geometry>
			</collision>
			<visual name="forearm1_visual">
				<pose>0.0561433036849963152 -0.0257850099915614278 -0 -0 -0 -0</pose>
				<geometry>
					<mesh>
						<uri>package://delta_robot_description/meshes/forearm1.stl</uri>
						<scale>0.001 0.001 0.001</scale>
					</mesh>
				</geometry>
				<material>
					<ambient>0.0 0.3 0.7 1</ambient>
					<diffuse>0.0 0.3 0.7 1</diffuse>
					<specular>0.8 0.8 0.8 1</specular>
				</material>
			</visual>
		</link>
		<link name="forearm2">
			<self_collide>false</self_collide>
			<pose>-0.074949672266278827 0.076816639779784729 0 0 0 0</pose>
			<inertial>
				<pose>0.0525 0.0 0.0 0 0 0</pose>
				<mass>0.15</mass>
				<inertia>
					<ixx>0.000073</ixx>
					<ixy>0</ixy>
					<ixz>0</ixz>
					<iyy>0.000158</iyy>
					<iyz>0</iyz>
					<izz>0.000191</izz>
				</inertia>
			</inertial>
			<collision name="forearm2_collision">
				<pose>-0.005741178152489557 0.061514032238822951 -0 -0 -0 -0</pose>
				<geometry>
					<mesh>
						<uri>package://delta_robot_description/meshes/forearm2.stl</uri>
						<scale>0.001 0.001 0.001</scale>
					</mesh>
				</geometry>
			</collision>
			<visual name="forearm2_visual">
				<pose>-0.005741178152489557 0.061514032238822951 -0 -0 -0 -0</pose>
				<geometry>
					<mesh>
						<uri>package://delta_robot_description/meshes/forearm2.stl</uri>
						<scale>0.001 0.001 0.001</scale>
					</mesh>
				</geometry>
				<material>
					<ambient>0.0 0.3 0.7 1</ambient>
					<diffuse>0.0 0.3 0.7 1</diffuse>
					<specular>0.8 0.8 0.8 1</specular>
				</material>
			</visual>
		</link>
		<link name="forearm3">
			<self_collide>false</self_collide>
			<pose>-0.029050325316846183 -0.103316640071477728 0 0 0 0</pose>
			<inertial>
				<pose>0.0 0.0 0.0 0 0 0</pose>
				<mass>0.15</mass>
				<inertia>
					<ixx>0.00015</ixx>
					<ixy>0</ixy>
					<ixz>0</ixz>
					<iyy>0.00019</iyy>
					<iyz>0</iyz>
					<izz>0.000072</izz>
				</inertia>
			</inertial>
			<collision name="forearm3_collision">
				<pose>-0.050402125564464335 -0.035729022253740722 -0 -0 -0 -0</pose>
				<geometry>
					<mesh>
						<uri>package://delta_robot_description/meshes/forearm3.stl</uri>
						<scale>0.001 0.001 0.001</scale>
					</mesh>
				</geometry>
			</collision>
			<visual name="forearm3_visual">
				<pose>-0.050402125564464335 -0.035729022253740722 -0 -0 -0 -0</pose>
				<geometry>
					<mesh>
						<uri>package://delta_robot_description/meshes/forearm3.stl</uri>
						<scale>0.001 0.001 0.001</scale>
					</mesh>
				</geometry>
				<material>
					<ambient>0.0 0.3 0.7 1</ambient>
					<diffuse>0.0 0.3 0.7 1</diffuse>
					<specular>0.8 0.8 0.8 1</specular>
				</material>
			</visual>
		</link>
		<link name="arm1">
			<self_collide>false</self_collide>
			<pose>0.20900000675206564793 -0.02478500079724475433 0.00000000000000005551 0 0 0</pose>
			<inertial>
				<pose>0.0 0.0 0.0 0 0 0</pose>
				<mass>0.05</mass>
				<inertia>
					<ixx>0.0002</ixx>
					<ixy>0</ixy>
					<ixz>0</ixz>
					<iyy>0.0002</iyy>
					<iyz>0</iyz>
					<izz>0.000002</izz>
				</inertia>
			</inertial>
			<collision name="arm1_collision">
				<pose>-0.08449980590506699085 -0.00035763973569721055 -0.06944278705156166354 -0 -0
					-0</pose>
				<geometry>
					<mesh>
						<uri>package://delta_robot_description/meshes/arm1.stl</uri>
						<scale>0.001 0.001 0.001</scale>
					</mesh>
				</geometry>
			</collision>
			<visual name="arm1_visual">
				<pose>-0.08449980590506699085 -0.00035763973569721055 -0.06944278705156166354 -0 -0
					-0</pose>
				<geometry>
					<mesh>
						<uri>package://delta_robot_description/meshes/arm1.stl</uri>
						<scale>0.001 0.001 0.001</scale>
					</mesh>
				</geometry>
				<material>
					<ambient>0.8 0.8 0.8 1</ambient>
					<diffuse>0.8 0.8 0.8 1</diffuse>
					<specular>0.5 0.5 0.5 1</specular>
				</material>
			</visual>
		</link>
		<link name="arm2">
			<self_collide>false</self_collide>
			<pose>0.209000006752065759 0.026215000865165896 0.0 0 0 0</pose>
			<inertial>
				<pose>0.0 0.0 0.0 0 0 0</pose>
				<mass>0.05</mass>
				<inertia>
					<ixx>0.0002</ixx>
					<ixy>0</ixy>
					<ixz>0</ixz>
					<iyy>0.0002</iyy>
					<iyz>0</iyz>
					<izz>0.000002</izz>
				</inertia>
			</inertial>
			<collision name="arm2_collision">
				<pose>-0.0844998151108035112 -0.0003575711572413187 -0.0694427488894385631 -0 -0 -0</pose>
				<geometry>
					<mesh>
						<uri>package://delta_robot_description/meshes/arm2.stl</uri>
						<scale>0.001 0.001 0.001</scale>
					</mesh>
				</geometry>
			</collision>
			<visual name="arm2_visual">
				<pose>-0.0844998151108035112 -0.0003575711572413187 -0.0694427488894385631 -0 -0 -0</pose>
				<geometry>
					<mesh>
						<uri>package://delta_robot_description/meshes/arm2.stl</uri>
						<scale>0.001 0.001 0.001</scale>
					</mesh>
				</geometry>
				<material>
					<ambient>0.8 0.8 0.8 1</ambient>
					<diffuse>0.8 0.8 0.8 1</diffuse>
					<specular>0.5 0.5 0.5 1</specular>
				</material>
			</visual>
		</link>
		<link name="arm3">
			<self_collide>false</self_collide>
			<pose>-0.083035563052801992 0.193391815637032449 0.0 0 0 0</pose>
			<inertial>
				<pose>0.0 0.0 0.0 0 0 0</pose>
				<mass>0.05</mass>
				<inertia>
					<ixx>0.0002</ixx>
					<ixy>0</ixy>
					<ixz>0</ixz>
					<iyy>0.0002</iyy>
					<iyz>0</iyz>
					<izz>0.000002</izz>
				</inertia>
			</inertial>
			<collision name="arm3_collision">
				<pose>0.042559566366243216 -0.073000265076894222 -0.069442721740443331 -0 -0 -0</pose>
				<geometry>
					<mesh>
						<uri>package://delta_robot_description/meshes/arm3.stl</uri>
						<scale>0.001 0.001 0.001</scale>
					</mesh>
				</geometry>
			</collision>
			<visual name="arm3_visual">
				<pose>0.042559566366243216 -0.073000265076894222 -0.069442721740443331 -0 -0 -0</pose>
				<geometry>
					<mesh>
						<uri>package://delta_robot_description/meshes/arm3.stl</uri>
						<scale>0.001 0.001 0.001</scale>
					</mesh>
				</geometry>
				<material>
					<ambient>0.8 0.8 0.8 1</ambient>
					<diffuse>0.8 0.8 0.8 1</diffuse>
					<specular>0.5 0.5 0.5 1</specular>
				</material>
			</visual>
		</link>
		<link name="arm4">
			<self_collide>false</self_collide>
			<pose>-0.12720286008549905 0.16789181480582666 0.00000000000000003 0 0 0</pose>
			<inertial>
				<pose>0.0 0.0 0.0 0 0 0</pose>
				<mass>0.05</mass>
				<inertia>
					<ixx>0.0002</ixx>
					<ixy>0</ixy>
					<ixz>0</ixz>
					<iyy>0.0002</iyy>
					<iyz>0</iyz>
					<izz>0.000002</izz>
				</inertia>
			</inertial>
			<collision name="arm4_collision">
				<pose>0.04255957311770086 -0.07300028116186946 -0.06944266492683357 -0 -0 -0</pose>
				<geometry>
					<mesh>
						<uri>package://delta_robot_description/meshes/arm4.stl</uri>
						<scale>0.001 0.001 0.001</scale>
					</mesh>
				</geometry>
			</collision>
			<visual name="arm4_visual">
				<pose>0.04255957311770086 -0.07300028116186946 -0.06944266492683357 -0 -0 -0</pose>
				<geometry>
					<mesh>
						<uri>package://delta_robot_description/meshes/arm4.stl</uri>
						<scale>0.001 0.001 0.001</scale>
					</mesh>
				</geometry>
				<material>
					<ambient>0.8 0.8 0.8 1</ambient>
					<diffuse>0.8 0.8 0.8 1</diffuse>
					<specular>0.5 0.5 0.5 1</specular>
				</material>
			</visual>
		</link>
		<link name="arm5">
			<self_collide>false</self_collide>
			<pose>-0.125964443612850363 -0.168606814913237035 -0.0 0 0 0</pose>
			<inertial>
				<pose>0.0 0.0 0.0 0 0 0</pose>
				<mass>0.05</mass>
				<inertia>
					<ixx>0.0002</ixx>
					<ixy>0</ixy>
					<ixz>0</ixz>
					<iyy>0.0002</iyy>
					<iyz>0</iyz>
					<izz>0.000002</izz>
				</inertia>
			</inertial>
			<collision name="arm5_collision">
				<pose>0.041940322084431984 0.073357789033613147 -0.069442674386891293 -0 -0 -0</pose>
				<geometry>
					<mesh>
						<uri>package://delta_robot_description/meshes/arm5.stl</uri>
						<scale>0.001 0.001 0.001</scale>
					</mesh>
				</geometry>
			</collision>
			<visual name="arm5_visual">
				<pose>0.041940322084431984 0.073357789033613147 -0.069442674386891293 -0 -0 -0</pose>
				<geometry>
					<mesh>
						<uri>package://delta_robot_description/meshes/arm5.stl</uri>
						<scale>0.001 0.001 0.001</scale>
					</mesh>
				</geometry>
				<material>
					<ambient>0.8 0.8 0.8 1</ambient>
					<diffuse>0.8 0.8 0.8 1</diffuse>
					<specular>0.5 0.5 0.5 1</specular>
				</material>
			</visual>
		</link>
		<link name="arm6">
			<self_collide>false</self_collide>
			<pose>-0.08179714655916207 -0.194106815708083 -0.0 0 0 0</pose>
			<inertial>
				<pose>0.0 0.0 0.0 0 0 0</pose>
				<mass>0.05</mass>
				<inertia>
					<ixx>0.0002</ixx>
					<ixy>0</ixy>
					<ixz>0</ixz>
					<iyy>0.0002</iyy>
					<iyz>0</iyz>
					<izz>0.000002</izz>
				</inertia>
			</inertial>
			<collision name="arm6_collision">
				<pose>0.04194032270292405 0.07335774565905394 -0.0694427245082631 -0 -0 -0</pose>
				<geometry>
					<mesh>
						<uri>package://delta_robot_description/meshes/arm6.stl</uri>
						<scale>0.001 0.001 0.001</scale>
					</mesh>
				</geometry>
			</collision>
			<visual name="arm6_visual">
				<pose>0.04194032270292405 0.07335774565905394 -0.0694427245082631 -0 -0 -0</pose>
				<geometry>
					<mesh>
						<uri>package://delta_robot_description/meshes/arm6.stl</uri>
						<scale>0.001 0.001 0.001</scale>
					</mesh>
				</geometry>
				<material>
					<ambient>0.8 0.8 0.8 1</ambient>
					<diffuse>0.8 0.8 0.8 1</diffuse>
					<specular>0.5 0.5 0.5 1</specular>
				</material>
			</visual>
		</link>
		<link name="dummy_arm1">
			<pose relative_to="EEBase">0.0399999106336249 -0.02550099696426037 0.0013148300673900516
				0 0 0</pose>
			<inertial>
				<mass>0.0001</mass>
				<inertia>
					<ixx>1e-9</ixx>
					<ixy>0</ixy>
					<ixz>0</ixz>
					<iyy>1e-9</iyy>
					<iyz>0</iyz>
					<izz>1e-9</izz>
				</inertia>
			</inertial>
		</link>
		<link name="dummy_arm2">
			<pose relative_to="EEBase">0.040000469970060175 0.025499003027132826
				0.0013155818141488852 0 0 0</pose>
			<inertial>
				<mass>0.0001</mass>
				<inertia>
					<ixx>1e-9</ixx>
					<ixy>0</ixy>
					<ixz>0</ixz>
					<iyy>1e-9</iyy>
					<iyz>0</iyz>
					<izz>1e-9</izz>
				</inertia>
			</inertial>
		</link>
		<link name="dummy_arm3">
			<pose relative_to="EEBase">0.0020839241609300384 0.04739068541483957
				0.0013161668581900799 0 0 0</pose>
			<inertial>
				<mass>0.0001</mass>
				<inertia>
					<ixx>1e-9</ixx>
					<ixy>0</ixy>
					<ixz>0</ixz>
					<iyy>1e-9</iyy>
					<iyz>0</iyz>
					<izz>1e-9</izz>
				</inertia>
			</inertial>
		</link>
		<link name="dummy_arm4">
			<pose relative_to="EEBase">-0.042083651096575976 0.02189116981419112
				0.001316096598864629 0 0 0</pose>
			<inertial>
				<mass>0.0001</mass>
				<inertia>
					<ixx>1e-9</ixx>
					<ixy>0</ixy>
					<ixz>0</ixz>
					<iyy>1e-9</iyy>
					<iyz>0</iyz>
					<izz>1e-9</izz>
				</inertia>
			</inertial>
		</link>
		<link name="dummy_arm5">
			<pose relative_to="EEBase">-0.042084131276305475 -0.021891363273269314
				0.0013154512385245632 0 0 0</pose>
			<inertial>
				<mass>0.0001</mass>
				<inertia>
					<ixx>1e-9</ixx>
					<ixy>0</ixy>
					<ixz>0</ixz>
					<iyy>1e-9</iyy>
					<iyz>0</iyz>
					<izz>1e-9</izz>
				</inertia>
			</inertial>
		</link>
		<link name="dummy_arm6">
			<pose relative_to="EEBase">0.002082884644770637 -0.04739184766402218
				0.0013147697510910207 0 0 0</pose>
			<inertial>
				<mass>0.0001</mass>
				<inertia>
					<ixx>1e-9</ixx>
					<ixy>0</ixy>
					<ixz>0</ixz>
					<iyy>1e-9</iyy>
					<iyz>0</iyz>
					<izz>1e-9</izz>
				</inertia>
			</inertial>
		</link>
		<link name="EEBase">
			<self_collide>false</self_collide>
			<pose>3.216945897263865e-08 -7.100634338227221e-08 -0.14020120674373254 0.0 -0.0 0.0</pose>
			<inertial>
				<pose>0.0 0.0 0.0 0 0 0</pose>
				<mass>0.04</mass>
				<inertia>
					<ixx>0.000016</ixx>
					<ixy>0</ixy>
					<ixz>0</ixz>
					<iyy>0.000016</iyy>
					<iyz>0</iyz>
					<izz>0.000032</izz>
				</inertia>
			</inertial>
			<collision name="EEBase_collision">
				<geometry>
					<mesh>
						<uri>package://delta_robot_description/meshes/EEBase.stl</uri>
						<scale>0.001 0.001 0.001</scale>
					</mesh>
				</geometry>
			</collision>
			<visual name="EEBase_visual">
				<geometry>
					<mesh>
						<uri>package://delta_robot_description/meshes/EEBase.stl</uri>
						<scale>0.001 0.001 0.001</scale>
					</mesh>
				</geometry>
				<material>
					<ambient>0.0 0.3 0.7 1</ambient>
					<diffuse>0.0 0.3 0.7 1</diffuse>
					<specular>0.8 0.8 0.8 1</specular>
				</material>
			</visual>
		</link>
		<link name="Bevel1">
			<self_collide>false</self_collide>
			<pose>0.022598242302743324 1.5023254582689155e-07 -0.15888522582472833 0.0 -0.0 0.0</pose>
			<inertial>
				<pose>0.0 0.0 0.0 0 0 0</pose>
				<mass>0.022887588345828228</mass>
				<inertia>
					<ixx>8.16053381778481e-07</ixx>
					<ixy>2.7732007178058698e-11</ixy>
					<ixz>2.8911296223732563e-11</ixz>
					<iyy>1.009084067003485e-06</iyy>
					<iyz>-3.055095842210755e-11</iyz>
					<izz>1.0090818193978419e-06</izz>
				</inertia>
			</inertial>
			<collision name="Bevel1_collision">
				<geometry>
					<mesh>
						<uri>package://delta_robot_description/meshes/Bevel1.stl</uri>
						<scale>0.001 0.001 0.001</scale>
					</mesh>
				</geometry>
			</collision>
			<visual name="Bevel1_visual">
				<geometry>
					<mesh>
						<uri>package://delta_robot_description/meshes/Bevel1.stl</uri>
						<scale>0.001 0.001 0.001</scale>
					</mesh>
				</geometry>
				<material>
					<ambient>0.7 0.5 0.1 1</ambient>
					<diffuse>0.7 0.5 0.1 1</diffuse>
					<specular>0.9 0.9 0.9 1</specular>
				</material>
			</visual>
		</link>
		<link name="Bevel2">
			<self_collide>false</self_collide>
			<pose>-0.02259839310274511 -2.726792334704168e-07 -0.1588851391512551 0.0 -0.0 0.0</pose>
			<inertial>
				<pose>0.0 0.0 0.0 0 0 0</pose>
				<mass>0.022888300784724754</mass>
				<inertia>
					<ixx>8.161183276055085e-07</ixx>
					<ixy>2.828124892893644e-11</ixy>
					<ixz>-2.772372468262674e-11</ixz>
					<iyy>1.0091288824910728e-06</iyy>
					<iyz>3.052772874275041e-11</iyz>
					<izz>1.0091285365408597e-06</izz>
				</inertia>
			</inertial>
			<collision name="Bevel2_collision">
				<geometry>
					<mesh>
						<uri>package://delta_robot_description/meshes/Bevel2.stl</uri>
						<scale>0.001 0.001 0.001</scale>
					</mesh>
				</geometry>
			</collision>
			<visual name="Bevel2_visual">
				<geometry>
					<mesh>
						<uri>package://delta_robot_description/meshes/Bevel2.stl</uri>
						<scale>0.001 0.001 0.001</scale>
					</mesh>
				</geometry>
				<material>
					<ambient>0.7 0.5 0.1 1</ambient>
					<diffuse>0.7 0.5 0.1 1</diffuse>
					<specular>0.9 0.9 0.9 1</specular>
				</material>
			</visual>
		</link>
		<link name="T">
			<self_collide>false</self_collide>
			<pose>2.578506345776477e-07 6.495428351427449e-05 -0.16393329788399613 0.0 -0.0 0.0</pose>
			<inertial>
				<pose>0.0 0.0 0.0 0 0 0</pose>
				<mass>0.014030555087990323</mass>
				<inertia>
					<ixx>9.053309944700328e-07</ixx>
					<ixy>1.0710002596982392e-12</ixy>
					<ixz>4.7122237259688054e-11</ixz>
					<iyy>2.1020063883147255e-06</iyy>
					<iyz>1.199054450867433e-08</iyz>
					<izz>1.260672844104325e-06</izz>
				</inertia>
			</inertial>
			<collision name="T_collision">
				<geometry>
					<mesh>
						<uri>package://delta_robot_description/meshes/T.stl</uri>
						<scale>0.001 0.001 0.001</scale>
					</mesh>
				</geometry>
			</collision>
			<visual name="T_visual">
				<geometry>
					<mesh>
						<uri>package://delta_robot_description/meshes/T.stl</uri>
						<scale>0.001 0.001 0.001</scale>
					</mesh>
				</geometry>
				<material>
					<ambient>0.7 0.7 0.7 1</ambient>
					<diffuse>0.7 0.7 0.7 1</diffuse>
					<specular>0.8 0.8 0.8 1</specular>
				</material>
			</visual>
		</link>
		<link name="EE">
			<self_collide>false</self_collide>
			<pose>0.00011232750203354883 0.00018478375659318564 -0.17343451463707285 0.0 -0.0 0.0</pose>
			<inertial>
				<pose>0.0 0.0 0.0 0 0 0</pose>
				<mass>0.030975</mass>
				<inertia>
					<ixx>2.7973e-06</ixx>
					<ixy>-2.4855e-09</ixy>
					<ixz>1.3258e-08</ixz>
					<iyy>2.7674e-06</iyy>
					<iyz>-3.3726e-08</iyz>
					<izz>4.6429e-06</izz>
				</inertia>
			</inertial>
			<collision name="EE_collision">
				<geometry>
					<mesh>
						<uri>package://delta_robot_description/meshes/EE.stl</uri>
						<scale>0.001 0.001 0.001</scale>
					</mesh>
				</geometry>
			</collision>
			<visual name="EE_visual">
				<geometry>
					<mesh>
						<uri>package://delta_robot_description/meshes/EE.stl</uri>
						<scale>0.001 0.001 0.001</scale>
					</mesh>
				</geometry>
				<material>
					<ambient>0.8 0.1 0.1 1</ambient>
					<diffuse>0.8 0.1 0.1 1</diffuse>
					<specular>0.5 0.5 0.5 1</specular>
					<emissive>0 0 0 1</emissive>
				</material>
			</visual>
		</link>
		<link name="camera_holder">
			<pose relative_to="EEBase">0.04 0 0 0 0 0</pose>
			<inertial>
				<mass>0.0001</mass>
				<inertia>
					<ixx>1e-9</ixx>
					<ixy>0</ixy>
					<ixz>0</ixz>
					<iyy>1e-9</iyy>
					<iyz>0</iyz>
					<izz>1e-9</izz>
				</inertia>
			</inertial>

			<collision name="camera_holder_collision">
				<geometry>
					<box>
						<size>0.03 0.01 0.01</size>
					</box>
				</geometry>
			</collision>

			<visual name="camera_holder_visual">
				<geometry>
					<box>
						<size>0.03 0.01 0.01</size>
					</box>
				</geometry>
			</visual>
		</link>
		<link name="camera_stick">
			<pose relative_to="camera_holder">0.01 0 -0.02 0 0 0</pose>
			<inertial>
				<mass>0.0001</mass>
				<inertia>
					<ixx>1e-9</ixx>
					<ixy>0</ixy>
					<ixz>0</ixz>
					<iyy>1e-9</iyy>
					<iyz>0</iyz>
					<izz>1e-9</izz>
				</inertia>
			</inertial>

			<collision name="camera_stick_collision">
				<geometry>
					<cylinder>
						<radius>0.005</radius>
						<length>0.035</length>
					</cylinder>
				</geometry>
			</collision>

			<visual name="camera_stick_visual">
				<geometry>
					<cylinder>
						<radius>0.005</radius>
						<length>0.035</length>
					</cylinder>
				</geometry>
			</visual>
		</link>
		<link name="camera_bar">
			<pose relative_to="camera_stick">-0.01 0 -0.02 0 0 0</pose>
			<inertial>
				<mass>0.0001</mass>
				<inertia>
					<ixx>1e-9</ixx>
					<ixy>0</ixy>
					<ixz>0</ixz>
					<iyy>1e-9</iyy>
					<iyz>0</iyz>
					<izz>1e-9</izz>
				</inertia>
			</inertial>

			<collision name="camera_bar_collision">
				<geometry>
					<box>
						<size>0.035 0.01 0.01</size>
					</box>
				</geometry>
			</collision>

			<visual name="camera_bar_visual">
				<geometry>
					<box>
						<size>0.035 0.01 0.01</size>
					</box>
				</geometry>
			</visual>
		</link>
		<link name="camera">
			<pose relative_to="camera_bar">-0.02 0 0 0 1.5708 0</pose>
			<inertial>
				<mass>0.0001</mass>
				<inertia>
					<ixx>1e-9</ixx>
					<ixy>0</ixy>
					<ixz>0</ixz>
					<iyy>1e-9</iyy>
					<iyz>0</iyz>
					<izz>1e-9</izz>
				</inertia>
			</inertial>
			<collision name="camera_collision">
				<geometry>
					<box>
						<size>0.01 0.01 0.01</size>
					</box>
				</geometry>
			</collision>
			<visual name="camera_visual">
				<geometry>
					<box>
						<size>0.01 0.01 0.01</size>
					</box>
				</geometry>
			</visual>
			<sensor name="camera1" type="camera">
				<pose>0 0 0 0 0 0</pose>
				<topic>camera/image_raw</topic>
				<update_rate>60.0</update_rate>
				<camera name="head">
					<horizontal_fov>1.3962634</horizontal_fov>
					<image>
						<width>800</width>
						<height>800</height>
						<format>R8G8B8</format>
					</image>
					<clip>
						<near>0.02</near>
						<far>300</far>
					</clip>
					<noise>
						<type>gaussian</type>
						<mean>0.0</mean>
						<stddev>0.007</stddev>
					</noise>
				</camera>
			</sensor>
		</link>
		<joint name="virtual_joint" type="fixed">
			<parent>world_link</parent>
			<child>base</child>
		</joint>
		<joint name="base_frame" type="fixed">
			<parent>base</parent>
			<child>Frame</child>
		</joint>

		<joint name="eye_to_hand_cam_joint" type="fixed">
			<parent>base</parent>
			<child>eye_to_hand_cam</child>
			<pose>0 0 0 0 0 0</pose>
		</joint>

		<joint name="jbf1" type="revolute">
			<parent>base</parent>
			<child>forearm1</child>
			<pose>-0.0 0.0 0 0 0 0</pose>
			<axis>
				<xyz>-5.65359340425105e-16 0.9999999999999969 1.1997618623413132e-15</xyz>
				<limit>
					<lower>-2.007128639793479</lower>
					<upper>2.007128639793479</upper>
					<effort>2.0</effort>
					<velocity>25.0</velocity>
				</limit>

			</axis>
		</joint>
		<joint name="jbf2" type="revolute">
			<parent>base</parent>
			<child>forearm2</child>
			<pose>0.0 -0.0 0 0 0 0</pose>
			<axis>
				<xyz>-0.8660254037844364 -0.49999999999999767 -1.0375984197275728e-16</xyz>
				<limit>
					<lower>-2.007128639793479</lower>
					<upper>2.007128639793479</upper>
					<effort>2.0</effort>
					<velocity>25.0</velocity>
				</limit>

			</axis>
		</joint>
		<joint name="jbf3" type="revolute">
			<parent>base</parent>
			<child>forearm3</child>
			<pose>0.0 0.0 0 0 0 0</pose>
			<axis>
				<xyz>0.8660254041960478 -0.4999999992870731 8.003401443675243e-16</xyz>
				<limit>
					<lower>-2.007128639793479</lower>
					<upper>2.007128639793479</upper>
					<effort>2.0</effort>
					<velocity>25.0</velocity>
				</limit>

			</axis>
		</joint>
		<joint name="ball1" type="ball">
			<parent>forearm1</parent>
			<child>arm1</child>
			<pose>0.0 0.0 0.0 0 0 0</pose>
		</joint>
		<joint name="ball2" type="ball">
			<parent>forearm3</parent>
			<child>arm6</child>
			<pose>-0.0 -0.0 0.0 0 0 0</pose>
		</joint>
		<joint name="ball3" type="ball">
			<parent>forearm3</parent>
			<child>arm5</child>
			<pose>-0.0 -0.0 0.0 0 0 0</pose>
		</joint>
		<joint name="ball4" type="ball">
			<parent>forearm2</parent>
			<child>arm4</child>
			<pose>-0.0 0.0 0.0 0 0 0</pose>
		</joint>
		<joint name="ball5" type="ball">
			<parent>forearm2</parent>
			<child>arm3</child>
			<pose>-0.0 0.0 0.0 0 0 0</pose>
		</joint>
		<joint name="ball6" type="ball">
			<parent>forearm1</parent>
			<child>arm2</child>
			<pose>0.0 0.0 0.0 0 0 0</pose>
		</joint><!-- 
		<joint name="ball7" type="ball">
			<parent>arm5</parent>
			<child>EEBase</child>
			<pose>-0.042084131276305475 -0.021891363273269314 0.0013154512385245632 0 0 0</pose>
		</joint>
		<joint name="ball8" type="ball">
			<parent>arm1</parent>
			<child>EEBase</child>
			<pose>0.0399999106336249 -0.02550099696426037 0.0013148300673900516 0 0 0</pose>
		</joint>
		<joint name="ball9" type="ball">
			<parent>arm3</parent>
			<child>EEBase</child>
			<pose>0.0020839241609300384 0.04739068541483957 0.0013161668581900799 0 0 0</pose>
		</joint>
		<joint name="ball10" type="ball">
			<parent>arm4</parent>
			<child>EEBase</child>
			<pose>-0.042083651096575976 0.02189116981419112 0.001316096598864629 0 0 0</pose>
		</joint>
		<joint name="ball11" type="ball">
			<parent>arm2</parent>
			<child>EEBase</child>
			<pose>0.040000469970060175 0.025499003027132826 0.0013155818141488852 0 0 0</pose>
		</joint>
		<joint name="ball12" type="ball">
			<parent>arm6</parent>
			<child>EEBase</child>
			<pose>0.002082884644770637 -0.04739184766402218 0.0013147697510910207 0 0 0</pose>
		</joint> -->
		<joint name="ball7" type="ball">
			<parent>arm5</parent>
			<child>dummy_arm5</child>
			<pose>-0.0 0.0 0.0 0 0 0</pose>
		</joint>

		<joint name="EEBase_to_dummy1" type="ball">
			<parent>EEBase</parent>
			<child>dummy_arm1</child>
		</joint>
		<joint name="EEBase_to_dummy2" type="ball">
			<parent>EEBase</parent>
			<child>dummy_arm2</child>
		</joint>
		<joint name="EEBase_to_dummy3" type="ball">
			<parent>EEBase</parent>
			<child>dummy_arm3</child>
		</joint>
		<joint name="EEBase_to_dummy4" type="ball">
			<parent>EEBase</parent>
			<child>dummy_arm4</child>
		</joint>
		<joint name="EEBase_to_dummy5" type="fixed">
			<parent>dummy_arm5</parent>
			<child>EEBase</child>
		</joint>
		<joint name="EEBase_to_dummy6" type="ball">
			<parent>EEBase</parent>
			<child>dummy_arm6</child>
		</joint>

		<joint name="camera_joint" type="fixed">
			<parent>EEBase</parent>
			<child>camera_holder</child>
		</joint>
		<joint name="camera_stick_joint" type="fixed">
			<parent>camera_holder</parent>
			<child>camera_stick</child>
		</joint>
		<joint name="camera_bar_joint" type="fixed">
			<parent>camera_stick</parent>
			<child>camera_bar</child>
		</joint>
		<joint name="camera_joint_final" type="fixed">
			<parent>camera_bar</parent>
			<child>camera</child>
		</joint>
		<!-- End Effector Control Joints -->
		<joint name="Bevelj1" type="revolute">
			<parent>EEBase</parent>
			<child>Bevel1</child>
			<axis>
				<xyz>1 0 0</xyz>
				<limit>
					<lower>-3</lower>
					<upper>3</upper>
					<effort>50.0</effort>
					<velocity>10.0</velocity>
				</limit>
				<dynamics>
					<damping>1.0</damping>
					<friction>0.01</friction>
				</dynamics>
			</axis>
		</joint>
		<joint name="Bevelj2" type="revolute">
			<parent>EEBase</parent>
			<child>Bevel2</child>
			<axis>
				<xyz>-1 0 0</xyz>
				<limit>
					<lower>-3</lower>
					<upper>3</upper>
					<effort>50.0</effort>
					<velocity>10.0</velocity>
				</limit>
				<dynamics>
					<damping>1.0</damping>
					<friction>0.01</friction>
				</dynamics>
			</axis>
		</joint>
		<joint name="Tj1" type="revolute">
			<parent>EEBase</parent>
			<child>T</child>
			<pose>0.0 0.0 0.005048116 0 0 0</pose>
			<axis>
				<xyz>1 0 0</xyz>
				<limit>
					<lower>-3.14159</lower>
					<upper>3.14159</upper>
					<effort>50.0</effort>
					<velocity>10.0</velocity>
				</limit>
				<dynamics>
					<damping>5.0</damping>
					<friction>0.01</friction>
				</dynamics>

			</axis>
		</joint>
		<joint name="BeveljEE" type="revolute">
			<parent>T</parent>
			<child>EE</child>
			<axis>
				<xyz>0 0 1</xyz>
				<limit>
					<lower>-3.14159</lower>
					<upper>3.14159</upper>
					<effort>50.0</effort>
					<velocity>10.0</velocity>
				</limit>
				<dynamics>
					<damping>5.0</damping>
					<friction>0.01</friction>
				</dynamics>

			</axis>
		</joint>

		<!-- ALL PLUGINS SECTION -->
		<plugin filename="libgz-sim-detachable-joint-system.so"
			name="gz::sim::systems::DetachableJoint">
			<parent_link>dummy_arm1</parent_link>
			<child_model>delta_robot</child_model>
			<child_link>arm1</child_link>
			<detach_topic>/delta/detach_arm1</detach_topic>
			<attach_topic>/delta/attach_arm1</attach_topic>
		</plugin>
		<plugin filename="libgz-sim-detachable-joint-system.so"
			name="gz::sim::systems::DetachableJoint">
			<parent_link>dummy_arm2</parent_link>
			<child_model>delta_robot</child_model>
			<child_link>arm2</child_link>
			<detach_topic>/delta/detach_arm2</detach_topic>
			<attach_topic>/delta/attach_arm2</attach_topic>
		</plugin>
		<plugin filename="libgz-sim-detachable-joint-system.so"
			name="gz::sim::systems::DetachableJoint">
			<parent_link>dummy_arm3</parent_link>
			<child_model>delta_robot</child_model>
			<child_link>arm3</child_link>
			<detach_topic>/delta/detach_arm3</detach_topic>
			<attach_topic>/delta/attach_arm3</attach_topic>
		</plugin>
		<plugin filename="libgz-sim-detachable-joint-system.so"
			name="gz::sim::systems::DetachableJoint">
			<parent_link>dummy_arm4</parent_link>
			<child_model>delta_robot</child_model>
			<child_link>arm4</child_link>
			<detach_topic>/delta/detach_arm4</detach_topic>
			<attach_topic>/delta/attach_arm4</attach_topic>
		</plugin>
		<plugin filename="libgz-sim-detachable-joint-system.so"
			name="gz::sim::systems::DetachableJoint">
			<parent_link>dummy_arm6</parent_link>
			<child_model>delta_robot</child_model>
			<child_link>arm6</child_link>
			<detach_topic>/delta/detach_arm6</detach_topic>
			<attach_topic>/delta/attach_arm6</attach_topic>
		</plugin>

		<plugin filename="gz_ros2_control-system" name="gz_ros2_control::GazeboSimROS2ControlPlugin">
			<parameters>$(find delta_robot_sim)/config/ros2_controllers.yaml</parameters>
		</plugin>

		<ros2_control name="IgnitionSystem" type="system">
			<hardware>
				<plugin>gz_ros2_control/GazeboSimSystem</plugin>
			</hardware>
			<joint name="jbf1">
				<command_interface name="position" />
				<state_interface name="position" />
				<state_interface name="velocity" />
			</joint>
			<joint name="jbf2">
				<command_interface name="position" />
				<state_interface name="position" />
				<state_interface name="velocity" />
			</joint>
			<joint name="jbf3">
				<command_interface name="position" />
				<state_interface name="position" />
				<state_interface name="velocity" />
			</joint>
			<joint name="Bevelj1">
				<command_interface name="position" />
				<state_interface name="position" />
				<state_interface name="velocity" />
			</joint>
			<joint name="Bevelj2">
				<command_interface name="position" />
				<state_interface name="position" />
				<state_interface name="velocity" />
			</joint>
			<joint name="Tj1">
				<command_interface name="position" />
				<state_interface name="position" />
				<state_interface name="velocity" />
			</joint>
			<joint name="BeveljEE">
				<command_interface name="position" />
				<state_interface name="position" />
				<state_interface name="velocity" />
			</joint>
		</ros2_control>
		<plugin filename="gz-sim-pose-publisher-system" name="gz::sim::systems::PosePublisher">
			<publish_link_pose>true</publish_link_pose>
			<use_pose_vector_msg>true</use_pose_vector_msg>
			<static_publisher>false</static_publisher>
			<static_update_frequency>100</static_update_frequency>
		</plugin>
	</model>
</sdf>