<robot name="delta_robot">
    <link name="Bevel1">
        <inertial>
            <mass value="0.0228876"/>
            <origin xyz="0 0 0" rpy="0 -0 0"/>
            <inertia ixx="8.16053e-07" ixy="2.7732e-11" ixz="2.89113e-11" iyy="1.00908e-06" iyz="-3.0551e-11" izz="1.00908e-06"/>
        </inertial>
        <visual>
            <origin xyz="0 0 0" rpy="0 -0 0"/>
            <geometry>
                <mesh filename="package://delta_robot_description/meshes/Bevel1.stl" scale="0.001 0.001 0.001"/>
            </geometry>
            <material name="Bevel1Bevel1_visual">
                <texture/>
                <color rgba="0.84 0.6 0.12 1.2"/>
            </material>
        </visual>
        <collision>
            <origin xyz="0 0 0" rpy="0 -0 0"/>
            <geometry>
                <mesh filename="package://delta_robot_description/meshes/Bevel1.stl" scale="0.001 0.001 0.001"/>
            </geometry>
        </collision>
    </link>
    <link name="Bevel2">
        <inertial>
            <mass value="0.0228883"/>
            <origin xyz="0 0 0" rpy="0 -0 0"/>
            <inertia ixx="8.16118e-07" ixy="2.82812e-11" ixz="-2.77237e-11" iyy="1.00913e-06" iyz="3.05277e-11" izz="1.00913e-06"/>
        </inertial>
        <visual>
            <origin xyz="0 0 0" rpy="0 -0 0"/>
            <geometry>
                <mesh filename="package://delta_robot_description/meshes/Bevel2.stl" scale="0.001 0.001 0.001"/>
            </geometry>
            <material name="Bevel2Bevel2_visual">
                <texture/>
                <color rgba="0.84 0.6 0.12 1.2"/>
            </material>
        </visual>
        <collision>
            <origin xyz="0 0 0" rpy="0 -0 0"/>
            <geometry>
                <mesh filename="package://delta_robot_description/meshes/Bevel2.stl" scale="0.001 0.001 0.001"/>
            </geometry>
        </collision>
    </link>
    <link name="EE">
        <inertial>
            <mass value="0.030975"/>
            <origin xyz="0 0 0" rpy="0 -0 0"/>
            <inertia ixx="2.7973e-06" ixy="-2.4855e-09" ixz="1.3258e-08" iyy="2.7674e-06" iyz="-3.3726e-08" izz="4.6429e-06"/>
        </inertial>
        <visual>
            <origin xyz="0 0 0" rpy="0 -0 0"/>
            <geometry>
                <mesh filename="package://delta_robot_description/meshes/EE.stl" scale="0.001 0.001 0.001"/>
            </geometry>
            <material name="EEEE_visual">
                <texture/>
                <color rgba="0.96 0.12 0.12 1.2"/>
            </material>
        </visual>
        <collision>
            <origin xyz="0 0 0" rpy="0 -0 0"/>
            <geometry>
                <mesh filename="package://delta_robot_description/meshes/EE.stl" scale="0.001 0.001 0.001"/>
            </geometry>
        </collision>
    </link>
    <link name="EEBase">
        <inertial>
            <mass value="0.04"/>
            <origin xyz="0 0 0" rpy="0 -0 0"/>
            <inertia ixx="1.6e-05" ixy="0" ixz="0" iyy="1.6e-05" iyz="0" izz="3.2e-05"/>
        </inertial>
        <visual>
            <origin xyz="0 0 0" rpy="0 -0 0"/>
            <geometry>
                <mesh filename="package://delta_robot_description/meshes/EEBase.stl" scale="0.001 0.001 0.001"/>
            </geometry>
            <material name="EEBaseEEBase_visual">
                <texture/>
                <color rgba="0 0.36 0.84 1.2"/>
            </material>
        </visual>
        <collision>
            <origin xyz="0 0 0" rpy="0 -0 0"/>
            <geometry>
                <mesh filename="package://delta_robot_description/meshes/EEBase.stl" scale="0.001 0.001 0.001"/>
            </geometry>
        </collision>
    </link>
    <link name="Frame">
        <inertial>
            <mass value="74.0844"/>
            <origin xyz="0 0 0" rpy="0 -0 0"/>
            <inertia ixx="4.0278" ixy="8.77306e-15" ixz="-2.62001e-15" iyy="4.09648" iyz="2.1416e-15" izz="4.61331"/>
        </inertial>
        <visual>
            <origin xyz="0 0 0" rpy="0 -0 0"/>
            <geometry>
                <mesh filename="package://delta_robot_description/meshes/Frame.stl" scale="0.001 0.001 0.001"/>
            </geometry>
            <material name="FrameFrame_visual">
                <texture/>
                <color rgba="0.24 0.24 0.24 1.2"/>
            </material>
        </visual>
        <collision>
            <origin xyz="0 0 0" rpy="0 -0 0"/>
            <geometry>
                <mesh filename="package://delta_robot_description/meshes/Frame.stl" scale="0.001 0.001 0.001"/>
            </geometry>
        </collision>
    </link>
    <link name="T">
        <inertial>
            <mass value="0.0140306"/>
            <origin xyz="0 0 -0.00504812" rpy="0 -0 0"/>
            <inertia ixx="9.05331e-07" ixy="1.071e-12" ixz="4.71222e-11" iyy="2.10201e-06" iyz="1.19905e-08" izz="1.26067e-06"/>
        </inertial>
        <visual>
            <origin xyz="0 0 -0.00504812" rpy="0 -0 0"/>
            <geometry>
                <mesh filename="package://delta_robot_description/meshes/T.stl" scale="0.001 0.001 0.001"/>
            </geometry>
            <material name="TT_visual">
                <texture/>
                <color rgba="0.84 0.84 0.84 1.2"/>
            </material>
        </visual>
        <collision>
            <origin xyz="0 0 -0.00504812" rpy="0 -0 0"/>
            <geometry>
                <mesh filename="package://delta_robot_description/meshes/T.stl" scale="0.001 0.001 0.001"/>
            </geometry>
        </collision>
    </link>
    <link name="arm1">
        <inertial>
            <mass value="0.05"/>
            <origin xyz="0 0 0" rpy="0 -0 0"/>
            <inertia ixx="0.0002" ixy="0" ixz="0" iyy="0.0002" iyz="0" izz="2e-06"/>
        </inertial>
        <visual>
            <origin xyz="-0.0844998 -0.00035764 -0.0694428" rpy="0 -0 0"/>
            <geometry>
                <mesh filename="package://delta_robot_description/meshes/arm1.stl" scale="0.001 0.001 0.001"/>
            </geometry>
            <material name="arm1arm1_visual">
                <texture/>
                <color rgba="0.96 0.96 0.96 1.2"/>
            </material>
        </visual>
        <collision>
            <origin xyz="-0.0844998 -0.00035764 -0.0694428" rpy="0 -0 0"/>
            <geometry>
                <mesh filename="package://delta_robot_description/meshes/arm1.stl" scale="0.001 0.001 0.001"/>
            </geometry>
        </collision>
    </link>
    <link name="arm2">
        <inertial>
            <mass value="0.05"/>
            <origin xyz="0 0 0" rpy="0 -0 0"/>
            <inertia ixx="0.0002" ixy="0" ixz="0" iyy="0.0002" iyz="0" izz="2e-06"/>
        </inertial>
        <visual>
            <origin xyz="-0.0844998 -0.000357571 -0.0694427" rpy="0 -0 0"/>
            <geometry>
                <mesh filename="package://delta_robot_description/meshes/arm2.stl" scale="0.001 0.001 0.001"/>
            </geometry>
            <material name="arm2arm2_visual">
                <texture/>
                <color rgba="0.96 0.96 0.96 1.2"/>
            </material>
        </visual>
        <collision>
            <origin xyz="-0.0844998 -0.000357571 -0.0694427" rpy="0 -0 0"/>
            <geometry>
                <mesh filename="package://delta_robot_description/meshes/arm2.stl" scale="0.001 0.001 0.001"/>
            </geometry>
        </collision>
    </link>
    <link name="arm3">
        <inertial>
            <mass value="0.05"/>
            <origin xyz="0 0 0" rpy="0 -0 0"/>
            <inertia ixx="0.0002" ixy="0" ixz="0" iyy="0.0002" iyz="0" izz="2e-06"/>
        </inertial>
        <visual>
            <origin xyz="0.0425596 -0.0730003 -0.0694427" rpy="0 -0 0"/>
            <geometry>
                <mesh filename="package://delta_robot_description/meshes/arm3.stl" scale="0.001 0.001 0.001"/>
            </geometry>
            <material name="arm3arm3_visual">
                <texture/>
                <color rgba="0.96 0.96 0.96 1.2"/>
            </material>
        </visual>
        <collision>
            <origin xyz="0.0425596 -0.0730003 -0.0694427" rpy="0 -0 0"/>
            <geometry>
                <mesh filename="package://delta_robot_description/meshes/arm3.stl" scale="0.001 0.001 0.001"/>
            </geometry>
        </collision>
    </link>
    <link name="arm4">
        <inertial>
            <mass value="0.05"/>
            <origin xyz="0 0 0" rpy="0 -0 0"/>
            <inertia ixx="0.0002" ixy="0" ixz="0" iyy="0.0002" iyz="0" izz="2e-06"/>
        </inertial>
        <visual>
            <origin xyz="0.0425596 -0.0730003 -0.0694427" rpy="0 -0 0"/>
            <geometry>
                <mesh filename="package://delta_robot_description/meshes/arm4.stl" scale="0.001 0.001 0.001"/>
            </geometry>
            <material name="arm4arm4_visual">
                <texture/>
                <color rgba="0.96 0.96 0.96 1.2"/>
            </material>
        </visual>
        <collision>
            <origin xyz="0.0425596 -0.0730003 -0.0694427" rpy="0 -0 0"/>
            <geometry>
                <mesh filename="package://delta_robot_description/meshes/arm4.stl" scale="0.001 0.001 0.001"/>
            </geometry>
        </collision>
    </link>
    <link name="arm5">
        <inertial>
            <mass value="0.05"/>
            <origin xyz="0 0 0" rpy="0 -0 0"/>
            <inertia ixx="0.0002" ixy="0" ixz="0" iyy="0.0002" iyz="0" izz="2e-06"/>
        </inertial>
        <visual>
            <origin xyz="0.0419403 0.0733578 -0.0694427" rpy="0 -0 0"/>
            <geometry>
                <mesh filename="package://delta_robot_description/meshes/arm5.stl" scale="0.001 0.001 0.001"/>
            </geometry>
            <material name="arm5arm5_visual">
                <texture/>
                <color rgba="0.96 0.96 0.96 1.2"/>
            </material>
        </visual>
        <collision>
            <origin xyz="0.0419403 0.0733578 -0.0694427" rpy="0 -0 0"/>
            <geometry>
                <mesh filename="package://delta_robot_description/meshes/arm5.stl" scale="0.001 0.001 0.001"/>
            </geometry>
        </collision>
    </link>
    <link name="arm6">
        <inertial>
            <mass value="0.05"/>
            <origin xyz="0 0 0" rpy="0 -0 0"/>
            <inertia ixx="0.0002" ixy="0" ixz="0" iyy="0.0002" iyz="0" izz="2e-06"/>
        </inertial>
        <visual>
            <origin xyz="0.0419403 0.0733577 -0.0694427" rpy="0 -0 0"/>
            <geometry>
                <mesh filename="package://delta_robot_description/meshes/arm6.stl" scale="0.001 0.001 0.001"/>
            </geometry>
            <material name="arm6arm6_visual">
                <texture/>
                <color rgba="0.96 0.96 0.96 1.2"/>
            </material>
        </visual>
        <collision>
            <origin xyz="0.0419403 0.0733577 -0.0694427" rpy="0 -0 0"/>
            <geometry>
                <mesh filename="package://delta_robot_description/meshes/arm6.stl" scale="0.001 0.001 0.001"/>
            </geometry>
        </collision>
    </link>
    <link name="base">
        <inertial>
            <mass value="3.66383"/>
            <origin xyz="0 0 0" rpy="0 -0 0"/>
            <inertia ixx="0.00804206" ixy="5.51609e-18" ixz="-2.37787e-18" iyy="0.00804206" iyz="-3.86957e-19" izz="0.0158386"/>
        </inertial>
        <visual>
            <origin xyz="0 0 0" rpy="0 -0 0"/>
            <geometry>
                <mesh filename="package://delta_robot_description/meshes/base.stl" scale="0.001 0.001 0.001"/>
            </geometry>
            <material name="basebase_visual">
                <texture/>
                <color rgba="0.24 0.24 0.24 1.2"/>
            </material>
        </visual>
        <collision>
            <origin xyz="0 0 0" rpy="0 -0 0"/>
            <geometry>
                <mesh filename="package://delta_robot_description/meshes/base.stl" scale="0.001 0.001 0.001"/>
            </geometry>
        </collision>
    </link>
    <link name="camera">
        <inertial>
            <mass value="0.0001"/>
            <origin xyz="2.77556e-17 0 2.77556e-17" rpy="0 -0 0"/>
            <inertia ixx="1e-09" ixy="0" ixz="0" iyy="1e-09" iyz="0" izz="1e-09"/>
        </inertial>
        <visual>
            <origin xyz="5.55112e-17 0 5.55112e-17" rpy="0 -0 0"/>
            <geometry>
                <box size="0.01 0.01 0.01"/>
            </geometry>
        </visual>
        <collision>
            <origin xyz="5.55112e-17 0 5.55112e-17" rpy="0 -0 0"/>
            <geometry>
                <box size="0.01 0.01 0.01"/>
            </geometry>
        </collision>
    </link>
    <link name="camera_bar">
        <inertial>
            <mass value="0.0001"/>
            <origin xyz="0 0 0" rpy="0 -0 0"/>
            <inertia ixx="1e-09" ixy="0" ixz="0" iyy="1e-09" iyz="0" izz="1e-09"/>
        </inertial>
        <visual>
            <origin xyz="0 0 0" rpy="0 -0 0"/>
            <geometry>
                <box size="0.035 0.01 0.01"/>
            </geometry>
        </visual>
        <collision>
            <origin xyz="0 0 0" rpy="0 -0 0"/>
            <geometry>
                <box size="0.035 0.01 0.01"/>
            </geometry>
        </collision>
    </link>
    <link name="camera_holder">
        <inertial>
            <mass value="0.0001"/>
            <origin xyz="0 0 0" rpy="0 -0 0"/>
            <inertia ixx="1e-09" ixy="0" ixz="0" iyy="1e-09" iyz="0" izz="1e-09"/>
        </inertial>
        <visual>
            <origin xyz="0 0 0" rpy="0 -0 0"/>
            <geometry>
                <box size="0.03 0.01 0.01"/>
            </geometry>
        </visual>
        <collision>
            <origin xyz="0 0 0" rpy="0 -0 0"/>
            <geometry>
                <box size="0.03 0.01 0.01"/>
            </geometry>
        </collision>
    </link>
    <link name="camera_stick">
        <inertial>
            <mass value="0.0001"/>
            <origin xyz="0 0 0" rpy="0 -0 0"/>
            <inertia ixx="1e-09" ixy="0" ixz="0" iyy="1e-09" iyz="0" izz="1e-09"/>
        </inertial>
        <visual>
            <origin xyz="0 0 0" rpy="0 -0 0"/>
            <geometry>
                <cylinder radius="0.005" length="0.035"/>
            </geometry>
        </visual>
        <collision>
            <origin xyz="0 0 0" rpy="0 -0 0"/>
            <geometry>
                <cylinder radius="0.005" length="0.035"/>
            </geometry>
        </collision>
    </link>
    <link name="dummy_arm1">
        <inertial>
            <mass value="0.0001"/>
            <origin xyz="0 0 0" rpy="0 -0 0"/>
            <inertia ixx="1e-09" ixy="0" ixz="0" iyy="1e-09" iyz="0" izz="1e-09"/>
        </inertial>
    </link>
    <link name="dummy_arm2">
        <inertial>
            <mass value="0.0001"/>
            <origin xyz="0 0 0" rpy="0 -0 0"/>
            <inertia ixx="1e-09" ixy="0" ixz="0" iyy="1e-09" iyz="0" izz="1e-09"/>
        </inertial>
    </link>
    <link name="dummy_arm3">
        <inertial>
            <mass value="0.0001"/>
            <origin xyz="0 0 0" rpy="0 -0 0"/>
            <inertia ixx="1e-09" ixy="0" ixz="0" iyy="1e-09" iyz="0" izz="1e-09"/>
        </inertial>
    </link>
    <link name="dummy_arm4">
        <inertial>
            <mass value="0.0001"/>
            <origin xyz="0 0 0" rpy="0 -0 0"/>
            <inertia ixx="1e-09" ixy="0" ixz="0" iyy="1e-09" iyz="0" izz="1e-09"/>
        </inertial>
    </link>
    <link name="dummy_arm5">
        <inertial>
            <mass value="0.0001"/>
            <origin xyz="0 0 0" rpy="0 -0 0"/>
            <inertia ixx="1e-09" ixy="0" ixz="0" iyy="1e-09" iyz="0" izz="1e-09"/>
        </inertial>
    </link>
    <link name="dummy_arm6">
        <inertial>
            <mass value="0.0001"/>
            <origin xyz="0 0 0" rpy="0 -0 0"/>
            <inertia ixx="1e-09" ixy="0" ixz="0" iyy="1e-09" iyz="0" izz="1e-09"/>
        </inertial>
    </link>
    <link name="eye_to_hand_cam">
        <inertial>
            <mass value="0.0001"/>
            <origin xyz="-4.16334e-17 0 2.77556e-17" rpy="0 -0 0"/>
            <inertia ixx="1e-09" ixy="0" ixz="0" iyy="1e-09" iyz="0" izz="1e-09"/>
        </inertial>
        <visual>
            <origin xyz="-8.32667e-17 0 5.55112e-17" rpy="0 -0 0"/>
            <geometry>
                <box size="0.01 0.01 0.01"/>
            </geometry>
        </visual>
        <collision>
            <origin xyz="-8.32667e-17 0 5.55112e-17" rpy="0 -0 0"/>
            <geometry>
                <box size="0.01 0.01 0.01"/>
            </geometry>
        </collision>
    </link>
    <link name="forearm1">
        <inertial>
            <mass value="0.15"/>
            <origin xyz="0.0525 0 0" rpy="0 -0 0"/>
            <inertia ixx="7.3e-05" ixy="0" ixz="0" iyy="0.000158" iyz="0" izz="0.000191"/>
        </inertial>
        <visual>
            <origin xyz="0.0561433 -0.025785 0" rpy="0 -0 0"/>
            <geometry>
                <mesh filename="package://delta_robot_description/meshes/forearm1.stl" scale="0.001 0.001 0.001"/>
            </geometry>
            <material name="forearm1forearm1_visual">
                <texture/>
                <color rgba="0 0.36 0.84 1.2"/>
            </material>
        </visual>
        <collision>
            <origin xyz="0.0561433 -0.025785 0" rpy="0 -0 0"/>
            <geometry>
                <mesh filename="package://delta_robot_description/meshes/forearm1.stl" scale="0.001 0.001 0.001"/>
            </geometry>
        </collision>
    </link>
    <link name="forearm2">
        <inertial>
            <mass value="0.15"/>
            <origin xyz="0.0525 0 0" rpy="0 -0 0"/>
            <inertia ixx="7.3e-05" ixy="0" ixz="0" iyy="0.000158" iyz="0" izz="0.000191"/>
        </inertial>
        <visual>
            <origin xyz="-0.00574118 0.061514 0" rpy="0 -0 0"/>
            <geometry>
                <mesh filename="package://delta_robot_description/meshes/forearm2.stl" scale="0.001 0.001 0.001"/>
            </geometry>
            <material name="forearm2forearm2_visual">
                <texture/>
                <color rgba="0 0.36 0.84 1.2"/>
            </material>
        </visual>
        <collision>
            <origin xyz="-0.00574118 0.061514 0" rpy="0 -0 0"/>
            <geometry>
                <mesh filename="package://delta_robot_description/meshes/forearm2.stl" scale="0.001 0.001 0.001"/>
            </geometry>
        </collision>
    </link>
    <link name="forearm3">
        <inertial>
            <mass value="0.15"/>
            <origin xyz="0 0 0" rpy="0 -0 0"/>
            <inertia ixx="0.00015" ixy="0" ixz="0" iyy="0.00019" iyz="0" izz="7.2e-05"/>
        </inertial>
        <visual>
            <origin xyz="-0.0504021 -0.035729 0" rpy="0 -0 0"/>
            <geometry>
                <mesh filename="package://delta_robot_description/meshes/forearm3.stl" scale="0.001 0.001 0.001"/>
            </geometry>
            <material name="forearm3forearm3_visual">
                <texture/>
                <color rgba="0 0.36 0.84 1.2"/>
            </material>
        </visual>
        <collision>
            <origin xyz="-0.0504021 -0.035729 0" rpy="0 -0 0"/>
            <geometry>
                <mesh filename="package://delta_robot_description/meshes/forearm3.stl" scale="0.001 0.001 0.001"/>
            </geometry>
        </collision>
    </link>
    <link name="world_link">
        <inertial>
            <mass value="1"/>
            <origin xyz="0 0 0" rpy="0 -0 0"/>
            <inertia ixx="1" ixy="0" ixz="0" iyy="1" iyz="0" izz="1"/>
        </inertial>
    </link>
    <joint name="Bevelj1" type="revolute">
        <origin xyz="0.0225982 2.21239e-07 -0.018684" rpy="0 -0 0"/>
        <axis xyz="1 0 0"/>
        <parent link="EEBase"/>
        <child link="Bevel1"/>
        <dynamics damping="1" friction="0.01"/>
        <limit effort="50" velocity="10" lower="-3" upper="3"/>
    </joint>
    <joint name="Bevelj2" type="revolute">
        <origin xyz="-0.0225984 -2.01673e-07 -0.0186839" rpy="0 -0 0"/>
        <axis xyz="-1 0 0"/>
        <parent link="EEBase"/>
        <child link="Bevel2"/>
        <dynamics damping="1" friction="0.01"/>
        <limit effort="50" velocity="10" lower="-3" upper="3"/>
    </joint>
    <joint name="BeveljEE" type="revolute">
        <origin xyz="0.00011207 0.000119829 -0.0145493" rpy="0 -0 0"/>
        <axis xyz="0 0 1"/>
        <parent link="T"/>
        <child link="EE"/>
        <dynamics damping="5" friction="0.01"/>
        <limit effort="50" velocity="10" lower="-3.14159" upper="3.14159"/>
    </joint>
    <joint name="EEBase_to_dummy1" type="floating">
        <origin xyz="0.0399999 -0.025501 0.00131483" rpy="0 -0 0"/>
        <axis xyz="0 0 0"/>
        <parent link="EEBase"/>
        <child link="dummy_arm1"/>
    </joint>
    <joint name="EEBase_to_dummy2" type="floating">
        <origin xyz="0.0400005 0.025499 0.00131558" rpy="0 -0 0"/>
        <axis xyz="0 0 0"/>
        <parent link="EEBase"/>
        <child link="dummy_arm2"/>
    </joint>
    <joint name="EEBase_to_dummy3" type="floating">
        <origin xyz="0.00208392 0.0473907 0.00131617" rpy="0 -0 0"/>
        <axis xyz="0 0 0"/>
        <parent link="EEBase"/>
        <child link="dummy_arm3"/>
    </joint>
    <joint name="EEBase_to_dummy4" type="floating">
        <origin xyz="-0.0420837 0.0218912 0.0013161" rpy="0 -0 0"/>
        <axis xyz="0 0 0"/>
        <parent link="EEBase"/>
        <child link="dummy_arm4"/>
    </joint>
    <joint name="EEBase_to_dummy5" type="fixed">
        <origin xyz="0.0420841 0.0218914 -0.00131545" rpy="0 -0 0"/>
        <axis xyz="0 0 0"/>
        <parent link="dummy_arm5"/>
        <child link="EEBase"/>
    </joint>
    <joint name="EEBase_to_dummy6" type="floating">
        <origin xyz="0.00208288 -0.0473918 0.00131477" rpy="0 -0 0"/>
        <axis xyz="0 0 0"/>
        <parent link="EEBase"/>
        <child link="dummy_arm6"/>
    </joint>
    <joint name="Tj1" type="revolute">
        <origin xyz="2.25681e-07 6.50253e-05 -0.018684" rpy="0 -0 0"/>
        <axis xyz="1 0 0"/>
        <parent link="EEBase"/>
        <child link="T"/>
        <dynamics damping="5" friction="0.01"/>
        <limit effort="50" velocity="10" lower="-3.14159" upper="3.14159"/>
    </joint>
    <joint name="ball1" type="floating">
        <origin xyz="0.105 -0.051285 5.551e-17" rpy="0 -0 0"/>
        <axis xyz="0 0 0"/>
        <parent link="forearm1"/>
        <child link="arm1"/>
    </joint>
    <joint name="ball2" type="floating">
        <origin xyz="-0.0527468 -0.0907902 0" rpy="0 -0 0"/>
        <axis xyz="0 0 0"/>
        <parent link="forearm3"/>
        <child link="arm6"/>
    </joint>
    <joint name="ball3" type="floating">
        <origin xyz="-0.0969141 -0.0652902 0" rpy="0 -0 0"/>
        <axis xyz="0 0 0"/>
        <parent link="forearm3"/>
        <child link="arm5"/>
    </joint>
    <joint name="ball4" type="floating">
        <origin xyz="-0.0522532 0.0910752 3e-17" rpy="0 -0 0"/>
        <axis xyz="0 0 0"/>
        <parent link="forearm2"/>
        <child link="arm4"/>
    </joint>
    <joint name="ball5" type="floating">
        <origin xyz="-0.00808589 0.116575 0" rpy="0 -0 0"/>
        <axis xyz="0 0 0"/>
        <parent link="forearm2"/>
        <child link="arm3"/>
    </joint>
    <joint name="ball6" type="floating">
        <origin xyz="0.105 -0.000284999 0" rpy="0 -0 0"/>
        <axis xyz="0 0 0"/>
        <parent link="forearm1"/>
        <child link="arm2"/>
    </joint>
    <joint name="ball7" type="floating">
        <origin xyz="0.0838803 0.146715 -0.138886" rpy="0 -0 0"/>
        <axis xyz="0 0 0"/>
        <parent link="arm5"/>
        <child link="dummy_arm5"/>
    </joint>
    <joint name="base_frame" type="fixed">
        <origin xyz="0 0 -0.0594536" rpy="0 -0 0"/>
        <axis xyz="0 0 0"/>
        <parent link="base"/>
        <child link="Frame"/>
    </joint>
    <joint name="camera_bar_joint" type="fixed">
        <origin xyz="-0.01 0 -0.02" rpy="0 -0 0"/>
        <axis xyz="0 0 0"/>
        <parent link="camera_stick"/>
        <child link="camera_bar"/>
    </joint>
    <joint name="camera_joint" type="fixed">
        <origin xyz="0.04 0 0" rpy="0 -0 0"/>
        <axis xyz="0 0 0"/>
        <parent link="EEBase"/>
        <child link="camera_holder"/>
    </joint>
    <joint name="camera_joint_final" type="fixed">
        <origin xyz="-0.02 0 0" rpy="0 1.5708 -0"/>
        <axis xyz="0 0 0"/>
        <parent link="camera_bar"/>
        <child link="camera"/>
    </joint>
    <joint name="camera_stick_joint" type="fixed">
        <origin xyz="0.01 0 -0.02" rpy="0 -0 0"/>
        <axis xyz="0 0 0"/>
        <parent link="camera_holder"/>
        <child link="camera_stick"/>
    </joint>
    <joint name="eye_to_hand_cam_joint" type="fixed">
        <origin xyz="0.2 0 0.035" rpy="0 1.5708 -0"/>
        <axis xyz="0 0 0"/>
        <parent link="base"/>
        <child link="eye_to_hand_cam"/>
    </joint>
    <joint name="jbf1" type="revolute">
        <origin xyz="0.104 0.0265 0" rpy="0 -0 0"/>
        <axis xyz="-5.65359e-16 1 1.19976e-15"/>
        <parent link="base"/>
        <child link="forearm1"/>
        <dynamics damping="0" friction="0"/>
        <limit effort="2" velocity="25" lower="-2.00713" upper="2.00713"/>
    </joint>
    <joint name="jbf2" type="revolute">
        <origin xyz="-0.0749497 0.0768166 0" rpy="0 -0 0"/>
        <axis xyz="-0.866025 -0.5 -1.0376e-16"/>
        <parent link="base"/>
        <child link="forearm2"/>
        <dynamics damping="0" friction="0"/>
        <limit effort="2" velocity="25" lower="-2.00713" upper="2.00713"/>
    </joint>
    <joint name="jbf3" type="revolute">
        <origin xyz="-0.0290503 -0.103317 0" rpy="0 -0 0"/>
        <axis xyz="0.866025 -0.5 8.0034e-16"/>
        <parent link="base"/>
        <child link="forearm3"/>
        <dynamics damping="0" friction="0"/>
        <limit effort="2" velocity="25" lower="-2.00713" upper="2.00713"/>
    </joint>
    <joint name="virtual_joint" type="fixed">
        <origin xyz="0 0 0" rpy="0 -0 0"/>
        <axis xyz="0 0 0"/>
        <parent link="world_link"/>
        <child link="base"/>
    </joint>
</robot>
